Workbook

Sheet Как пользоваться
A1: План уроков по грамматике Spotlight
A3: «Темы × классы»: строка = подтема (один короткий урок: видео → правило → мини-тест). Подтемы сгруппированы по темам: Past Simple делится на правильные/неправильные глаголы, утверждение, отрицание, вопросы, орфографию, каждое значение; сравнения времён — отдельными подтемами.
A4: В клетке класса — где в учебнике (М9 (9b) = Module 9, урок 9b) и статус: «новое» — подтема в Spotlight впервые; «расш.» — была, здесь добавлено; «повт.» — дана снова. Наведите на клетку — во всплывающей подсказке что именно дано (лица, слова-сигналы, список глаголов).
A5: Цвет клетки: оттенок = группа вебинара (оранжевый 7–9 лет, голубой 10+), насыщенность = статус (ярче — новое, бледнее — повторение).
A6: Группы вебинаров: 7–9 лет = Spotlight 2–4 (у Spotlight 2 нет грамматического справочника, поэтому 2 класса нет; 4 класс — в группе 7–9, его темы идут в вебинарах 7–9). 10+ = Spotlight 5–11.
A7: Цвет подтемы: ЗЕЛЁНЫЙ — есть видео; ЖЁЛТЫЙ — вебинар в расписании (материалы есть, после вебинара появится видео; рядом дата, «проведён, ждём видео» — если дата прошла); ОРАНЖЕВЫЙ — видео нет, но есть материалы в папке; КРАСНЫЙ — ничего нет. Если подтема нужна обеим группам, цвет — по худшей из двух; по каждой группе — в колонках «Видео 7–9» / «Видео 10+» (видео / вебинар / материалы / нет), рядом названия видео, дата вебинара или папки с материалами. «—» — подтема этой группе не нужна.
A8: «Уроки»: один урок = подтема × группа. Если подтема повторяется в нескольких классах одной группы, это один и тот же урок (Мл-… для 7–9 лет, Ст-… для 10+): в колонке «Где используется» — все классы и модули. Видео подтягивается из «Темы × классы»; «Готовность» отмечается здесь.
A9: «Папки уроков»: Spotlight / класс / модуль / тема (папка) / подтема — какой урок (№) куда положить. Видео и готовность подтягиваются из «Уроков».
A10: «Пересечения»: одна и та же вещь в двух-трёх темах — где предлагаю держать урок, где поставить ссылку.
A11: Утверждение, отрицание и вопрос разделены там, где книга даёт их по отдельности; где справочник даёт их вместе (модальные глаголы старших классов) — одна подтема.
A12: «Кандидаты в вебинары»: по каждой группе — темы с красными подтемами (нет ни видео, ни материалов); отсортировано по классу, где тема появляется. Из них выбираем следующие вебинары.
A13: «Итоги»: сколько уроков сделать каждой группе, у скольких есть видео, сколько готово и опубликовано.
A15: Источник: грамматический справочник учебников (Use of English — оглавление и приложения). Подробный объём по строкам — в Spotlight_грамматика.xlsx.

Sheet Темы × классы
A1: № | B1: Блок | C1: Категория | D1: Тема | E1: Подтема (урок) | F1: Группы | G1: 3 кл. | H1: 4 кл. | I1: 5 кл. | J1: 6 кл. | K1: 7 кл. | L1: 8 кл. | M1: 9 кл. | N1: 10 кл. | O1: 11 кл. | P1: Видео 7–9 | Q1: Вебинар 7–9 (название / ссылка) | R1: Видео 10+ | S1: Вебинар 10+ (название / ссылка) | T1: Комментарий
A2: 1 | B2: Грамматика | C2: Глаголы: времена | D2: Past Simple | E2: Past Simple: правильные глаголы — утверждение (-ed) | F2: обе | G2: М4 · новое | H2: М6 · повт. | I2: М9 (9b) · повт. | J2: М7 (7a) · повт. | K2: М2 · повт. | L2: М1 (1c) · повт. | M2: М3 (3c) · повт. | N2: М5 (5c) · повт. | O2: М1 (1c) · повт. | P2: видео | Q2: Past Simple Regular+a funny story | R2: видео | S2: Past Tenses Review + travel and holidays Places to go.Past Simple regular verbs. (по названию)
A3: 2 | B3: Грамматика | C3: Глаголы: времена | D3: Past Simple | E3: Past Simple: правильные глаголы — отрицание (didn't + V) | F3: обе | G3: М4 · новое | H3: М6 · повт. | I3: М9 (9b) · повт. | J3: М7 (7a) · повт. | K3: М2 · повт. | L3: М1 (1c) · повт. | P3: видео | Q3: Past Simple regular questions and negatives | R3: нет
A4: 3 | B4: Грамматика | C4: Глаголы: времена | D4: Past Simple | E4: Past Simple: правильные глаголы — вопросы (Did …?) | F4: обе | G4: М4 · новое | H4: М6 · повт. | I4: М9 (9b) · повт. | J4: М7 (7a) · повт. | K4: М2 · повт. | L4: М1 (1c) · повт. | P4: видео | Q4: Past Simple regular questions and negatives | R4: нет
A5: 4 | B5: Грамматика | C5: Глаголы: времена | D5: Past Simple | E5: Past Simple: краткие ответы (Yes, I did / No, I didn't) | F5: обе | G5: М4 · новое | H5: М6 · повт. | I5: М9 (9b) · повт. М9 (9c) · повт. | J5: М7 (7a) · повт. М7 (7b) · повт. | K5: М2 · повт. | L5: М1 (1c) · повт. | P5: видео | Q5: Past Simple regular questions and negatives | R5: нет
A6: 5 | B6: Грамматика | C6: Глаголы: времена | D6: Past Simple | E6: Past Simple: орфография -ed | F6: обе | G6: М4 · новое | H6: М6 · повт. | I6: М9 (9b) · повт. | J6: М7 (7a) · повт. | K6: М2 · повт. | L6: М1 (1c) · расш. | M6: М3 (3c) · повт. | N6: М5 (5c) · повт. | O6: М1 (1c) · повт. | P6: вебинар | Q6: вебинар 19.11 (по расписанию): Past Simple: неправильные глаголы — отрицание и вопросы | R6: видео | S6: Places to go.Past Simple regular verbs. (по названию)
A7: 6 | B7: Грамматика | C7: Глаголы: времена | D7: Past Simple | E7: Past Simple: произношение -ed (/t/, /d/, /ɪd/) | F7: 7–9 | G7: М4 · новое | H7: М6 · повт. | P7: вебинар | Q7: вебинар 19.11 (по расписанию): Past Simple: неправильные глаголы — отрицание и вопросы | R7: —
A8: 7 | B8: Грамматика | C8: Глаголы: времена | D8: Past Simple | E8: Past Simple: неправильные глаголы — утверждение | F8: обе | G8: М5 · новое | H8: М7 · повт. | I8: М9 (9c) · расш. | J8: М7 (7b) · расш. | K8: М2 · повт. | L8: М1 (1c) · повт. | M8: М3 (3c) · повт. | N8: М5 (5c) · повт. | O8: М1 (1c) · повт. | P8: видео | Q8: Past Simple irregular verbs | R8: видео | S8: Movies+Irregular verbs Past Tenses Review + travel and holidays
A9: 8 | B9: Грамматика | C9: Глаголы: времена | D9: Past Simple | E9: Past Simple: неправильные глаголы — отрицание (didn't go) | F9: обе | G9: М5 · новое | H9: М7 · повт. | I9: М9 (9c) · повт. | J9: М7 (7b) · повт. | K9: М2 · повт. | P9: вебинар | Q9: вебинар 19.11 (по расписанию): Past Simple: неправильные глаголы — отрицание и вопросы | R9: нет
A10: 9 | B10: Грамматика | C10: Глаголы: времена | D10: Past Simple | E10: Past Simple: неправильные глаголы — вопросы (Did … go?) | F10: обе | G10: М5 · новое | H10: М7 · повт. | I10: М9 (9c) · повт. | J10: М7 (7b) · повт. | K10: М2 · повт. | P10: вебинар | Q10: вебинар 19.11 (по расписанию): Past Simple: неправильные глаголы — отрицание и вопросы | R10: нет
A11: 10 | B11: Грамматика | C11: Глаголы: времена | D11: Past Simple | E11: Past Simple: одна форма для всех лиц, исключение was/were | F11: 10+ | L11: М1 (1c) · новое | M11: М3 (3c) · повт. | N11: М5 (5c) · повт. | O11: М1 (1c) · повт. | P11: — | R11: видео | S11: Movies+Irregular verbs
A12: 11 | B12: Грамматика | C12: Глаголы: времена | D12: Past Simple | E12: Past Simple: значение — действие в прошлом (yesterday, ago) | F12: обе | G12: М4 · новое М5 · повт. | H12: М6 · повт. | I12: М9 (9b) · повт. | J12: М7 (7a) · повт. | K12: М2 · расш. | L12: М1 (1c) · повт. | M12: М3 (3c) · повт. | N12: М5 (5c) · повт. | O12: М1 (1c) · повт. | P12: видео | Q12: Past Simple Regular+a funny story Past Simple irregular verbs | R12: видео | S12: Movies+Irregular verbs Past Tenses Review + travel and holidays Places to go.Past Simple regular verbs. (по названию) Tense overview (Prese...mple, Present Perfect) Tenses overview 1
A13: 12 | B13: Грамматика | C13: Глаголы: времена | D13: Past Simple | E13: Past Simple: значение — действие в указанное время в прошлом | F13: 10+ | L13: М1 (1c) · новое | M13: М3 (3c) · повт. | N13: М5 (5c) · повт. | O13: М1 (1c) · повт. | P13: — | R13: видео | S13: Tense overview (Prese...mple, Present Perfect) Tenses overview 1
A14: 13 | B14: Грамматика | C14: Глаголы: времена | D14: Past Simple | E14: Past Simple: значение — повторяющиеся действия и привычки в прошлом | F14: 10+ | L14: М1 (1c) · новое | M14: М3 (3c) · повт. | N14: М5 (5c) · повт. | O14: М1 (1c) · повт. | P14: — | R14: нет
A15: 14 | B15: Грамматика | C15: Глаголы: времена | D15: Past Simple | E15: Past Simple: значение — последовательные действия | F15: 10+ | L15: М1 (1c) · новое | M15: М3 (3c) · повт. | N15: М5 (5c) · повт. | O15: М1 (1c) · повт. | P15: — | R15: вебинар | S15: вебинар 24.11 (по расписанию): Narrative tenses + history материалы: History + narrative tenses
A16: 15 | B16: Грамматика | C16: Глаголы: времена | D16: Past Simple | E16: Past Simple: значение — завершённые действия без связи с настоящим | F16: 10+ | M16: М3 (3c) · новое | N16: М5 (5c) · повт. | O16: М1 (1c) · повт. | P16: — | R16: нет
A17: 16 | B17: Грамматика | C17: Глаголы: времена | D17: Present Continuous | E17: Present Continuous: утверждение (am/is/are + V-ing) | F17: обе | G17: М7 · новое | H17: М1 · повт. | I17: М6 (6b) · повт. | J17: М5 (5a) · повт. | L17: М1 (1c) · повт. | M17: М1 (1c) · повт. | N17: М1 (1c) · повт. | O17: М1 (1c) · повт. | P17: видео | Q17: Favourite activities Present Cont Present Continuous+ activities | R17: нет
A18: 17 | B18: Грамматика | C18: Глаголы: времена | D18: Present Continuous | E18: Present Continuous: отрицание (I'm not / isn't / aren't) | F18: обе | G18: М7 · новое | H18: М1 · повт. | I18: М6 (6b) · повт. | J18: М5 (5b) · повт. | L18: М1 (1c) · повт. | P18: вебинар | Q18: вебинар 12.11 (по расписанию): Present Continuous: отрицание и вопросы материалы: Present Continuous questions and negatives | R18: нет
A19: 18 | B19: Грамматика | C19: Глаголы: времена | D19: Present Continuous | E19: Present Continuous: общие вопросы (Am/Is/Are …?) | F19: обе | G19: М7 · новое | H19: М1 · повт. | I19: М6 (6b) · повт. | J19: М5 (5b) · повт. | L19: М1 (1c) · повт. | P19: вебинар | Q19: вебинар 12.11 (по расписанию): Present Continuous: отрицание и вопросы материалы: Present Continuous questions and negatives | R19: нет
A20: 19 | B20: Грамматика | C20: Глаголы: времена | D20: Present Continuous | E20: Present Continuous: краткие ответы (Yes, I am / No, he isn't) | F20: обе | G20: М7 · новое | H20: М1 · повт. | I20: М6 (6b) · повт. | J20: М5 (5b) · повт. | L20: М1 (1c) · повт. | P20: вебинар | Q20: вебинар 12.11 (по расписанию): Present Continuous: отрицание и вопросы материалы: Present Continuous questions and negatives | R20: нет
A21: 20 | B21: Грамматика | C21: Глаголы: времена | D21: Present Continuous | E21: Present Continuous: орфография -ing | F21: 10+ | I21: М6 (6b) · новое | J21: М5 (5b) · повт. | L21: М1 (1c) · расш. | M21: М1 (1c) · повт. | N21: М1 (1c) · повт. | O21: М1 (1c) · повт. | P21: — | R21: нет
A22: 21 | B22: Грамматика | C22: Глаголы: времена | D22: Present Continuous | E22: Present Continuous: значение — действие сейчас (now) | F22: обе | G22: М7 · новое | H22: М1 · повт. | I22: М6 (6b) · повт. | J22: М5 (5b) · повт. | K22: М1 · повт. | L22: М1 (1c) · повт. | M22: М1 (1c) · повт. | N22: М1 (1c) · повт. | O22: М1 (1c) · повт. | P22: видео | Q22: Favourite activities Present Cont Present Continuous+ activities Present Simple vs Present Continuous | R22: видео | S22: Present tenses (review...cter and relationships
A23: 22 | B23: Грамматика | C23: Глаголы: времена | D23: Present Continuous | E23: Present Continuous: значение — действие в настоящий период (these days) | F23: 10+ | I23: М6 (6b) · новое | J23: М5 (5b) · расш. | K23: М1 · повт. | M23: М1 (1c) · повт. | N23: М1 (1c) · повт. | O23: М1 (1c) · повт. | P23: — | R23: видео | S23: Present tenses (review...cter and relationships
A24: 23 | B24: Грамматика | C24: Глаголы: времена | D24: Present Continuous | E24: Present Continuous: значение — запланированное будущее | F24: 10+ | J24: М5 (5b) · новое М10 (10b) · повт. | K24: М1 · повт. | L24: М1 (1c) · расш. | M24: М1 (1c) · повт. | N24: М1 (1c) · повт. | O24: М1 (1c) · повт. | P24: — | R24: видео | S24: Your schedule + Prese...ous for future meaning
A25: 24 | B25: Грамматика | C25: Глаголы: времена | D25: Present Continuous | E25: Present Continuous: значение — временные ситуации | F25: 10+ | L25: М1 (1c) · новое | M25: М1 (1c) · повт. | N25: М1 (1c) · повт. | O25: М1 (1c) · повт. | P25: — | R25: видео | S25: Present tenses (review...cter and relationships
A26: 25 | B26: Грамматика | C26: Глаголы: времена | D26: Present Continuous | E26: Present Continuous: значение — меняющиеся и развивающиеся ситуации | F26: 10+ | K26: М1 · новое | L26: М1 (1c) · повт. | M26: М1 (1c) · повт. | N26: М1 (1c) · повт. | O26: М1 (1c) · повт. | P26: — | R26: нет
A27: 26 | B27: Грамматика | C27: Глаголы: времена | D27: Present Continuous | E27: Present Continuous: значение — always + раздражение | F27: 10+ | K27: М1 · новое | L27: М1 (1c) · расш. | M27: М1 (1c) · повт. | N27: М1 (1c) · повт. | O27: М1 (1c) · повт. | P27: — | R27: нет
A28: 27 | B28: Грамматика | C28: Глаголы: времена | D28: Present Simple | E28: Present Simple: утверждение (I/you/we/they V, he/she/it V-s) | F28: обе | G28: М3 · новое | H28: М2 · повт. | I28: М5 (5a) · повт. | J28: М4 (4a) · повт. | L28: М1 (1c) · повт. | M28: М1 (1c) · повт. | N28: М1 (1c) · повт. | O28: М1 (1c) · повт. | P28: видео | Q28: Free time Like _ing | R28: нет
A29: 28 | B29: Грамматика | C29: Глаголы: времена | D29: Present Simple | E29: Present Simple: отрицание (don't/doesn't) | F29: обе | G29: М3 · новое | H29: М2 · повт. | I29: М5 (5b) · повт. | J29: М4 (4a) · повт. | L29: М1 (1c) · повт. | P29: видео | Q29: Free time Like _ing | R29: нет
A30: 29 | B30: Грамматика | C30: Глаголы: времена | D30: Present Simple | E30: Present Simple: общие вопросы (Do/Does …?) | F30: обе | G30: М3 · новое | H30: М2 · повт. | I30: М5 (5b) · повт. | J30: М4 (4a) · повт. | L30: М1 (1c) · повт. | P30: вебинар | Q30: вебинар 09.11 (по расписанию): Present Simple: вопросы и краткие ответы | R30: нет
A31: 30 | B31: Грамматика | C31: Глаголы: времена | D31: Present Simple | E31: Present Simple: краткие ответы (Yes, I do / No, he doesn't) | F31: обе | G31: М3 · новое | H31: М2 · повт. | I31: М5 (5b) · повт. | J31: М4 (4b) · повт. | L31: М1 (1c) · повт. | P31: вебинар | Q31: вебинар 09.11 (по расписанию): Present Simple: вопросы и краткие ответы | R31: нет
A32: 31 | B32: Грамматика | C32: Глаголы: времена | D32: Present Simple | E32: Present Simple: орфография окончания -s/-es (3 л. ед. ч.) | F32: обе | G32: М8 · новое | H32: М2 · повт. | I32: М5 (5a) · повт. | J32: М4 (4a) · повт. | L32: М1 (1c) · повт. | M32: М1 (1c) · повт. | N32: М1 (1c) · повт. | O32: М1 (1c) · повт. | P32: вебинар | Q32: вебинар 09.11 (по расписанию): Present Simple: вопросы и краткие ответы | R32: нет
A33: 32 | B33: Грамматика | C33: Глаголы: времена | D33: Present Simple | E33: Present Simple: произношение окончания -s/-es (/s/, /z/, /ɪz/) | F33: 7–9 | G33: М8 · новое | H33: М2 · повт. | P33: нет | R33: —
A34: 33 | B34: Грамматика | C34: Глаголы: времена | D34: Present Simple | E34: Present Simple: значение — регулярные действия, распорядок дня, привычки | F34: обе | G34: М3 · новое М8 · повт. | H34: М2 · расш. | I34: М5 (5a) · расш. | J34: М4 (4a) · расш. | K34: М1 · повт. | L34: М1 (1c) · повт. | M34: М1 (1c) · повт. | N34: М1 (1c) · повт. | O34: М1 (1c) · повт. | P34: видео | Q34: A day in my life+adver...ency in Present Simple Present Simple vs Present Continuous | R34: видео | S34: Daily Activities. Adverbs of Frequency in Pr.S. Tense overview (Prese...mple, Present Perfect) Tenses overview 1 Present tenses (review...cter and relationships
A35: 34 | B35: Грамматика | C35: Глаголы: времена | D35: Present Simple | E35: Present Simple: значение — постоянные состояния и действия | F35: 10+ | I35: М5 (5a) · новое | J35: М4 (4a) · повт. | K35: М1 · повт. | L35: М1 (1c) · повт. | M35: М1 (1c) · повт. | N35: М1 (1c) · повт. | O35: М1 (1c) · повт. | P35: — | R35: видео | S35: Present tenses (review...cter and relationships
A36: 35 | B36: Грамматика | C36: Глаголы: времена | D36: Present Simple | E36: Present Simple: значение — непреложные истины и законы природы | F36: 10+ | I36: М5 (5a) · новое | J36: М4 (4a) · повт. | K36: М1 · повт. | P36: — | R36: нет
A37: 36 | B37: Грамматика | C37: Глаголы: времена | D37: Present Simple | E37: Present Simple: значение — расписания и программы (будущее по расписанию) | F37: 10+ | K37: М1 · новое | L37: М1 (1c) · расш. | M37: М1 (1c) · повт. | N37: М1 (1c) · повт. | O37: М1 (1c) · повт. | P37: — | R37: видео | S37: Present Simple for shedules and timetables
A38: 37 | B38: Грамматика | C38: Глаголы: времена | D38: Present Simple | E38: Present Simple: значение — чувства и эмоции | F38: 10+ | K38: М1 · новое | P38: — | R38: нет
A39: 38 | B39: Грамматика | C39: Глаголы: времена | D39: Present Simple | E39: Present Simple: значение — обзоры, спортивные комментарии, повествование | F39: 10+ | K39: М1 · новое | M39: М1 (1c) · повт. | N39: М1 (1c) · повт. | O39: М1 (1c) · повт. | P39: — | R39: нет
A40: 39 | B40: Грамматика | C40: Глаголы: времена | D40: Present Simple | E40: Present Simple: значение — восклицания (Here comes …!) | F40: 10+ | M40: М1 (1c) · новое | N40: М1 (1c) · повт. | O40: М1 (1c) · повт. | P40: — | R40: нет
...

Sheet Уроки
A1: № урока | B1: Группа | C1: Блок | D1: Тема | E1: Подтема (урок) | F1: Где используется (класс · модуль · статус) | G1: Папок | H1: Видео | I1: Вебинар | J1: Готовность | K1: Комментарий
A2: Мл-001 | B2: 7–9 | C2: Грамматика | D2: Past Simple | E2: Past Simple: правильные глаголы — утверждение (-ed) | F2: 3 кл. · М4 · новое 4 кл. · М6 · повт. | G2: 2 | H2: ='Темы × классы'!P2 | I2: ='Темы × классы'!Q2&"" | J2: не начат
A3: Мл-002 | B3: 7–9 | C3: Грамматика | D3: Past Simple | E3: Past Simple: правильные глаголы — отрицание (didn't + V) | F3: 3 кл. · М4 · новое 4 кл. · М6 · повт. | G3: 2 | H3: ='Темы × классы'!P3 | I3: ='Темы × классы'!Q3&"" | J3: не начат
A4: Мл-003 | B4: 7–9 | C4: Грамматика | D4: Past Simple | E4: Past Simple: правильные глаголы — вопросы (Did …?) | F4: 3 кл. · М4 · новое 4 кл. · М6 · повт. | G4: 2 | H4: ='Темы × классы'!P4 | I4: ='Темы × классы'!Q4&"" | J4: не начат
A5: Мл-004 | B5: 7–9 | C5: Грамматика | D5: Past Simple | E5: Past Simple: краткие ответы (Yes, I did / No, I didn't) | F5: 3 кл. · М4 · новое 4 кл. · М6 · повт. | G5: 2 | H5: ='Темы × классы'!P5 | I5: ='Темы × классы'!Q5&"" | J5: не начат
A6: Мл-005 | B6: 7–9 | C6: Грамматика | D6: Past Simple | E6: Past Simple: орфография -ed | F6: 3 кл. · М4 · новое 4 кл. · М6 · повт. | G6: 2 | H6: ='Темы × классы'!P6 | I6: ='Темы × классы'!Q6&"" | J6: не начат
A7: Мл-006 | B7: 7–9 | C7: Грамматика | D7: Past Simple | E7: Past Simple: произношение -ed (/t/, /d/, /ɪd/) | F7: 3 кл. · М4 · новое 4 кл. · М6 · повт. | G7: 2 | H7: ='Темы × классы'!P7 | I7: ='Темы × классы'!Q7&"" | J7: не начат
A8: Мл-007 | B8: 7–9 | C8: Грамматика | D8: Past Simple | E8: Past Simple: неправильные глаголы — утверждение | F8: 3 кл. · М5 · новое 4 кл. · М7 · повт. | G8: 2 | H8: ='Темы × классы'!P8 | I8: ='Темы × классы'!Q8&"" | J8: не начат
A9: Мл-008 | B9: 7–9 | C9: Грамматика | D9: Past Simple | E9: Past Simple: неправильные глаголы — отрицание (didn't go) | F9: 3 кл. · М5 · новое 4 кл. · М7 · повт. | G9: 2 | H9: ='Темы × классы'!P9 | I9: ='Темы × классы'!Q9&"" | J9: не начат
A10: Мл-009 | B10: 7–9 | C10: Грамматика | D10: Past Simple | E10: Past Simple: неправильные глаголы — вопросы (Did … go?) | F10: 3 кл. · М5 · новое 4 кл. · М7 · повт. | G10: 2 | H10: ='Темы × классы'!P10 | I10: ='Темы × классы'!Q10&"" | J10: не начат
A11: Мл-010 | B11: 7–9 | C11: Грамматика | D11: Past Simple | E11: Past Simple: значение — действие в прошлом (yesterday, ago) | F11: 3 кл. · М4 · новое 3 кл. · М5 · повт. 4 кл. · М6 · повт. | G11: 3 | H11: ='Темы × классы'!P12 | I11: ='Темы × классы'!Q12&"" | J11: не начат
A12: Мл-011 | B12: 7–9 | C12: Грамматика | D12: Present Continuous | E12: Present Continuous: утверждение (am/is/are + V-ing) | F12: 3 кл. · М7 · новое 4 кл. · М1 · повт. | G12: 2 | H12: ='Темы × классы'!P17 | I12: ='Темы × классы'!Q17&"" | J12: не начат
A13: Мл-012 | B13: 7–9 | C13: Грамматика | D13: Present Continuous | E13: Present Continuous: отрицание (I'm not / isn't / aren't) | F13: 3 кл. · М7 · новое 4 кл. · М1 · повт. | G13: 2 | H13: ='Темы × классы'!P18 | I13: ='Темы × классы'!Q18&"" | J13: не начат
A14: Мл-013 | B14: 7–9 | C14: Грамматика | D14: Present Continuous | E14: Present Continuous: общие вопросы (Am/Is/Are …?) | F14: 3 кл. · М7 · новое 4 кл. · М1 · повт. | G14: 2 | H14: ='Темы × классы'!P19 | I14: ='Темы × классы'!Q19&"" | J14: не начат
A15: Мл-014 | B15: 7–9 | C15: Грамматика | D15: Present Continuous | E15: Present Continuous: краткие ответы (Yes, I am / No, he isn't) | F15: 3 кл. · М7 · новое 4 кл. · М1 · повт. | G15: 2 | H15: ='Темы × классы'!P20 | I15: ='Темы × классы'!Q20&"" | J15: не начат
A16: Мл-015 | B16: 7–9 | C16: Грамматика | D16: Present Continuous | E16: Present Continuous: значение — действие сейчас (now) | F16: 3 кл. · М7 · новое 4 кл. · М1 · повт. | G16: 2 | H16: ='Темы × классы'!P22 | I16: ='Темы × классы'!Q22&"" | J16: не начат
A17: Мл-016 | B17: 7–9 | C17: Грамматика | D17: Present Simple | E17: Present Simple: утверждение (I/you/we/they V, he/she/it V-s) | F17: 3 кл. · М3 · новое 4 кл. · М2 · повт. | G17: 2 | H17: ='Темы × классы'!P28 | I17: ='Темы × классы'!Q28&"" | J17: не начат
A18: Мл-017 | B18: 7–9 | C18: Грамматика | D18: Present Simple | E18: Present Simple: отрицание (don't/doesn't) | F18: 3 кл. · М3 · новое 4 кл. · М2 · повт. | G18: 2 | H18: ='Темы × классы'!P29 | I18: ='Темы × классы'!Q29&"" | J18: не начат
A19: Мл-018 | B19: 7–9 | C19: Грамматика | D19: Present Simple | E19: Present Simple: общие вопросы (Do/Does …?) | F19: 3 кл. · М3 · новое 4 кл. · М2 · повт. | G19: 2 | H19: ='Темы × классы'!P30 | I19: ='Темы × классы'!Q30&"" | J19: не начат
A20: Мл-019 | B20: 7–9 | C20: Грамматика | D20: Present Simple | E20: Present Simple: краткие ответы (Yes, I do / No, he doesn't) | F20: 3 кл. · М3 · новое 4 кл. · М2 · повт. | G20: 2 | H20: ='Темы × классы'!P31 | I20: ='Темы × классы'!Q31&"" | J20: не начат
A21: Мл-020 | B21: 7–9 | C21: Грамматика | D21: Present Simple | E21: Present Simple: орфография окончания -s/-es (3 л. ед. ч.) | F21: 3 кл. · М8 · новое 4 кл. · М2 · повт. | G21: 2 | H21: ='Темы × классы'!P32 | I21: ='Темы × классы'!Q32&"" | J21: не начат
A22: Мл-021 | B22: 7–9 | C22: Грамматика | D22: Present Simple | E22: Present Simple: произношение окончания -s/-es (/s/, /z/, /ɪz/) | F22: 3 кл. · М8 · новое 4 кл. · М2 · повт. | G22: 2 | H22: ='Темы × классы'!P33 | I22: ='Темы × классы'!Q33&"" | J22: не начат
A23: Мл-022 | B23: 7–9 | C23: Грамматика | D23: Present Simple | E23: Present Simple: значение — регулярные действия, распорядок дня, привычки | F23: 3 кл. · М3 · новое 3 кл. · М8 · повт. 4 кл. · М2 · расш. | G23: 3 | H23: ='Темы × классы'!P34 | I23: ='Темы × классы'!Q34&"" | J23: не начат
A24: Мл-023 | B24: 7–9 | C24: Грамматика | D24: Future Simple (will) | E24: Future Simple (will): утверждение (will/'ll + V) | F24: 4 кл. · М8 · новое | G24: 1 | H24: ='Темы × классы'!P42 | I24: ='Темы × классы'!Q42&"" | J24: не начат
A25: Мл-024 | B25: 7–9 | C25: Грамматика | D25: Future Simple (will) | E25: Future Simple (will): отрицание (will not/won't) | F25: 4 кл. · М8 · новое | G25: 1 | H25: ='Темы × классы'!P43 | I25: ='Темы × классы'!Q43&"" | J25: не начат
A26: Мл-025 | B26: 7–9 | C26: Грамматика | D26: Future Simple (will) | E26: Future Simple (will): вопросы и краткие ответы | F26: 4 кл. · М8 · новое | G26: 1 | H26: ='Темы × классы'!P44 | I26: ='Темы × классы'!Q44&"" | J26: не начат
A27: Мл-026 | B27: 7–9 | C27: Грамматика | D27: Future Simple (will) | E27: Future Simple (will): значение — предсказание/предположение | F27: 4 кл. · М8 · новое | G27: 1 | H27: ='Темы × классы'!P45 | I27: ='Темы × классы'!Q45&"" | J27: не начат
A28: Мл-027 | B28: 7–9 | C28: Грамматика | D28: Future Simple (will) | E28: Future Simple (will): значение — решение в момент речи | F28: 4 кл. · М8 · новое | G28: 1 | H28: ='Темы × классы'!P46 | I28: ='Темы × классы'!Q46&"" | J28: не начат
A29: Мл-028 | B29: 7–9 | C29: Грамматика | D29: Future Simple (will) | E29: Future Simple (will): значение — обещания | F29: 4 кл. · М8 · новое | G29: 1 | H29: ='Темы × классы'!P47 | I29: ='Темы × классы'!Q47&"" | J29: не начат
A30: Мл-029 | B30: 7–9 | C30: Грамматика | D30: Present Simple vs Present Continuous | E30: Present Simple vs Present Continuous: привычка vs сейчас | F30: 4 кл. · М4 · новое | G30: 1 | H30: ='Темы × классы'!P54 | I30: ='Темы × классы'!Q54&"" | J30: не начат
A31: Мл-030 | B31: 7–9 | C31: Грамматика | D31: be going to | E31: be going to: утверждение (am/is/are going to + V) | F31: 4 кл. · М8 · новое | G31: 1 | H31: ='Темы × классы'!P58 | I31: ='Темы × классы'!Q58&"" | J31: не начат
A32: Мл-031 | B32: 7–9 | C32: Грамматика | D32: be going to | E32: be going to: отрицание | F32: 4 кл. · М8 · новое | G32: 1 | H32: ='Темы × классы'!P59 | I32: ='Темы × классы'!Q59&"" | J32: не начат
A33: Мл-032 | B33: 7–9 | C33: Грамматика | D33: be going to | E33: be going to: вопросы и краткие ответы | F33: 4 кл. · М8 · новое | G33: 1 | H33: ='Темы × классы'!P60 | I33: ='Темы × классы'!Q60&"" | J33: не начат
A34: Мл-033 | B34: 7–9 | C34: Грамматика | D34: be going to | E34: be going to: значение — планы и намерения | F34: 4 кл. · М8 · новое | G34: 1 | H34: ='Темы × классы'!P61 | I34: ='Темы × классы'!Q61&"" | J34: не начат
A35: Мл-034 | B35: 7–9 | C35: Грамматика | D35: can (ability) | E35: can (ability): значение — умение; утверждение can + глагол без to | F35: 3 кл. · М5 · новое | G35: 1 | H35: ='Темы × классы'!P125 | I35: ='Темы × классы'!Q125&"" | J35: не начат
A36: Мл-035 | B36: 7–9 | C36: Грамматика | D36: can (ability) | E36: can (ability): отрицание — cannot / can't | F36: 3 кл. · М5 · новое | G36: 1 | H36: ='Темы × классы'!P126 | I36: ='Темы × классы'!Q126&"" | J36: не начат
A37: Мл-036 | B37: 7–9 | C37: Грамматика | D37: can (ability) | E37: can (ability): вопросы и краткие ответы | F37: 3 кл. · М5 · новое | G37: 1 | H37: ='Темы × классы'!P127 | I37: ='Темы × классы'!Q127&"" | J37: не начат
A38: Мл-037 | B38: 7–9 | C38: Грамматика | D38: have got | E38: have got: утверждение — have got / has got (полные и краткие формы) | F38: 3 кл. · М5 · новое | G38: 1 | H38: ='Темы × классы'!P128 | I38: ='Темы × классы'!Q128&"" | J38: не начат
A39: Мл-038 | B39: 7–9 | C39: Грамматика | D39: have got | E39: have got: отрицание — haven't got / hasn't got | F39: 3 кл. · М5 · новое | G39: 1 | H39: ='Темы × классы'!P129 | I39: ='Темы × классы'!Q129&"" | J39: не начат
A40: Мл-039 | B40: 7–9 | C40: Грамматика | D40: have got | E40: have got: вопросы и краткие ответы | F40: 3 кл. · М5 · новое | G40: 1 | H40: ='Темы × классы'!P130 | I40: ='Темы × классы'!Q130&"" | J40: не начат
...

Sheet Папки уроков
A1: Класс | B1: Модуль | C1: Урок учебника | D1: Тема (папка) | E1: Подтема (урок) | F1: № урока | G1: В учебнике | H1: Что именно в этом классе | I1: Группа | J1: Видео | K1: Готовность | L1: Путь
A2: 3 | B2: Module 1 · School days | D2: to be (Present) | E2: to be (Present): утверждение — am/is/are, полные и краткие формы | F2: Мл-047 | G2: новое | H2: все лица; I am/I'm, he is/he's, we are/we're… | I2: 7–9 | J2: =IFERROR(INDEX('Уроки'!$H:$H,MATCH(F2,'Уроки'!$A:$A,0)),"") | K2: =IFERROR(INDEX('Уроки'!$J:$J,MATCH(F2,'Уроки'!$A:$A,0)),"") | L2: Spotlight / 3 класс / Module 1 · School days / to be (Present) / to be (Present): утверждение — am/is/are, полные и краткие формы
A3: 3 | B3: Module 1 · School days | D3: to be (Present) | E3: to be (Present): отрицание — am not / isn't / aren't | F3: Мл-048 | G3: новое | H3: полные и краткие: I'm not, isn't, aren't | I3: 7–9 | J3: =IFERROR(INDEX('Уроки'!$H:$H,MATCH(F3,'Уроки'!$A:$A,0)),"") | K3: =IFERROR(INDEX('Уроки'!$J:$J,MATCH(F3,'Уроки'!$A:$A,0)),"") | L3: Spotlight / 3 класс / Module 1 · School days / to be (Present) / to be (Present): отрицание — am not / isn't / aren't
A4: 3 | B4: Module 1 · School days | D4: to be (Present) | E4: to be (Present): вопросы и краткие ответы | F4: Мл-049 | G4: новое | H4: Am I? Is he? Are you?; Yes, I am / No, I'm not | I4: 7–9 | J4: =IFERROR(INDEX('Уроки'!$H:$H,MATCH(F4,'Уроки'!$A:$A,0)),"") | K4: =IFERROR(INDEX('Уроки'!$J:$J,MATCH(F4,'Уроки'!$A:$A,0)),"") | L4: Spotlight / 3 класс / Module 1 · School days / to be (Present) / to be (Present): вопросы и краткие ответы
A5: 3 | B5: Module 2 · Family moments | D5: to be (Past: was/were) | E5: to be (Past): утверждение — was / were | F5: Мл-043 | G5: новое | H5: I/he/she/it was; you/we/they were | I5: 7–9 | J5: =IFERROR(INDEX('Уроки'!$H:$H,MATCH(F5,'Уроки'!$A:$A,0)),"") | K5: =IFERROR(INDEX('Уроки'!$J:$J,MATCH(F5,'Уроки'!$A:$A,0)),"") | L5: Spotlight / 3 класс / Module 2 · Family moments / to be (Past: was/were) / to be (Past): утверждение — was / were
A6: 3 | B6: Module 2 · Family moments | D6: to be (Past: was/were) | E6: to be (Past): отрицание — wasn't / weren't | F6: Мл-044 | G6: новое | H6: полные и краткие: was not/wasn't, were not/weren't | I6: 7–9 | J6: =IFERROR(INDEX('Уроки'!$H:$H,MATCH(F6,'Уроки'!$A:$A,0)),"") | K6: =IFERROR(INDEX('Уроки'!$J:$J,MATCH(F6,'Уроки'!$A:$A,0)),"") | L6: Spotlight / 3 класс / Module 2 · Family moments / to be (Past: was/were) / to be (Past): отрицание — wasn't / weren't
A7: 3 | B7: Module 2 · Family moments | D7: to be (Past: was/were) | E7: to be (Past): вопросы и краткие ответы | F7: Мл-045 | G7: новое | H7: was/were перед подлежащим; Yes, I was / No, they weren't | I7: 7–9 | J7: =IFERROR(INDEX('Уроки'!$H:$H,MATCH(F7,'Уроки'!$A:$A,0)),"") | K7: =IFERROR(INDEX('Уроки'!$J:$J,MATCH(F7,'Уроки'!$A:$A,0)),"") | L7: Spotlight / 3 класс / Module 2 · Family moments / to be (Past: was/were) / to be (Past): вопросы и краткие ответы
A8: 3 | B8: Module 2 · Family moments | D8: to be (Past: was/were) | E8: to be (Past): слова-указатели прошедшего времени | F8: Мл-046 | G8: новое | H8: yesterday, last week/month/year, two days ago, in 1975 | I8: 7–9 | J8: =IFERROR(INDEX('Уроки'!$H:$H,MATCH(F8,'Уроки'!$A:$A,0)),"") | K8: =IFERROR(INDEX('Уроки'!$J:$J,MATCH(F8,'Уроки'!$A:$A,0)),"") | L8: Spotlight / 3 класс / Module 2 · Family moments / to be (Past: was/were) / to be (Past): слова-указатели прошедшего времени
A9: 3 | B9: Module 2 · Family moments | D9: Plurals (regular) | E9: Plurals (regular): основное правило — + -s | F9: Мл-059 | G9: новое | H9: только это правило: pen — pens, book — books | I9: 7–9 | J9: =IFERROR(INDEX('Уроки'!$H:$H,MATCH(F9,'Уроки'!$A:$A,0)),"") | K9: =IFERROR(INDEX('Уроки'!$J:$J,MATCH(F9,'Уроки'!$A:$A,0)),"") | L9: Spotlight / 3 класс / Module 2 · Family moments / Plurals (regular) / Plurals (regular): основное правило — + -s
A10: 3 | B10: Module 2 · Family moments | D10: Possessive adjectives | E10: Possessive adjectives: формы my, your, his, her, its, our, their | F10: Мл-079 | G10: новое | H10: полная таблица I — my … they — their | I10: 7–9 | J10: =IFERROR(INDEX('Уроки'!$H:$H,MATCH(F10,'Уроки'!$A:$A,0)),"") | K10: =IFERROR(INDEX('Уроки'!$J:$J,MATCH(F10,'Уроки'!$A:$A,0)),"") | L10: Spotlight / 3 класс / Module 2 · Family moments / Possessive adjectives / Possessive adjectives: формы my, your, his, her, its, our, their
A11: 3 | B11: Module 2 · Family moments | D11: Possessive adjectives | E11: Possessive adjectives: значение — принадлежность и отношения между людьми | F11: Мл-080 | G11: новое | H11: перед существительным: This is my mother | I11: 7–9 | J11: =IFERROR(INDEX('Уроки'!$H:$H,MATCH(F11,'Уроки'!$A:$A,0)),"") | K11: =IFERROR(INDEX('Уроки'!$J:$J,MATCH(F11,'Уроки'!$A:$A,0)),"") | L11: Spotlight / 3 класс / Module 2 · Family moments / Possessive adjectives / Possessive adjectives: значение — принадлежность и отношения между людьми
A12: 3 | B12: Module 3 · All the things I like! | D12: Present Simple | E12: Present Simple: утверждение (I/you/we/they V, he/she/it V-s) | F12: Мл-016 | G12: новое | H12: все лица: I like, he/she/it likes | I12: 7–9 | J12: =IFERROR(INDEX('Уроки'!$H:$H,MATCH(F12,'Уроки'!$A:$A,0)),"") | K12: =IFERROR(INDEX('Уроки'!$J:$J,MATCH(F12,'Уроки'!$A:$A,0)),"") | L12: Spotlight / 3 класс / Module 3 · All the things I like! / Present Simple / Present Simple: утверждение (I/you/we/they V, he/she/it V-s)
A13: 3 | B13: Module 3 · All the things I like! | D13: Present Simple | E13: Present Simple: отрицание (don't/doesn't) | F13: Мл-017 | G13: новое | H13: do not/don't, does not/doesn't | I13: 7–9 | J13: =IFERROR(INDEX('Уроки'!$H:$H,MATCH(F13,'Уроки'!$A:$A,0)),"") | K13: =IFERROR(INDEX('Уроки'!$J:$J,MATCH(F13,'Уроки'!$A:$A,0)),"") | L13: Spotlight / 3 класс / Module 3 · All the things I like! / Present Simple / Present Simple: отрицание (don't/doesn't)
... A24: 3 | B24: Module 4 · Come in and play! | D24: Past Simple | E24: Past Simple: правильные глаголы — вопросы (Did …?) | F24: Мл-003 | G24: новое | H24: Did … work? | I24: 7–9 | J24: =IFERROR(INDEX('Уроки'!$H:$H,MATCH(F24,'Уроки'!$A:$A,0)),"") | K24: =IFERROR(INDEX('Уроки'!$J:$J,MATCH(F24,'Уроки'!$A:$A,0)),"") | L24: Spotlight / 3 класс / Module 4 · Come in and play! / Past Simple / Past Simple: правильные глаголы — вопросы (Did …?)
A25: 3 | B25: Module 4 · Come in and play! | D25: Past Simple | E25: Past Simple: краткие ответы (Yes, I did / No, I didn't) | F25: Мл-004 | G25: новое | I25: 7–9 | J25: =IFERROR(INDEX('Уроки'!$H:$H,MATCH(F25,'Уроки'!$A:$A,0)),"") | K25: =IFERROR(INDEX('Уроки'!$J:$J,MATCH(F25,'Уроки'!$A:$A,0)),"") | L25: Spotlight / 3 класс / Module 4 · Come in and play! / Past Simple / Past Simple: краткие ответы (Yes, I did / No, I didn't)
A26: 3 | B26: Module 4 · Come in and play! | D26: Past Simple | E26: Past Simple: орфография -ed | F26: Мл-005 | G26: новое | H26: danced, studied, travelled, planned | I26: 7–9 | J26: =IFERROR(INDEX('Уроки'!$H:$H,MATCH(F26,'Уроки'!$A:$A,0)),"") | K26: =IFERROR(INDEX('Уроки'!$J:$J,MATCH(F26,'Уроки'!$A:$A,0)),"") | L26: Spotlight / 3 класс / Module 4 · Come in and play! / Past Simple / Past Simple: орфография -ed
A27: 3 | B27: Module 4 · Come in and play! | D27: Past Simple | E27: Past Simple: произношение -ed (/t/, /d/, /ɪd/) | F27: Мл-006 | G27: новое | H27: washed /t/, played /d/, wanted /ɪd/ | I27: 7–9 | J27: =IFERROR(INDEX('Уроки'!$H:$H,MATCH(F27,'Уроки'!$A:$A,0)),"") | K27: =IFERROR(INDEX('Уроки'!$J:$J,MATCH(F27,'Уроки'!$A:$A,0)),"") | L27: Spotlight / 3 класс / Module 4 · Come in and play! / Past Simple / Past Simple: произношение -ed (/t/, /d/, /ɪd/)
A28: 3 | B28: Module 4 · Come in and play! | D28: Past Simple | E28: Past Simple: значение — действие в прошлом (yesterday, ago) | F28: Мл-010 | G28: новое | H28: yesterday, last week/month/year, two days ago, in 1975 | I28: 7–9 | J28: =IFERROR(INDEX('Уроки'!$H:$H,MATCH(F28,'Уроки'!$A:$A,0)),"") | K28: =IFERROR(INDEX('Уроки'!$J:$J,MATCH(F28,'Уроки'!$A:$A,0)),"") | L28: Spotlight / 3 класс / Module 4 · Come in and play! / Past Simple / Past Simple: значение — действие в прошлом (yesterday, ago)
A29: 3 | B29: Module 4 · Come in and play! | D29: Possessive case ('s) | E29: Possessive case ('s): 's в ед. ч. — принадлежность | F29: Мл-063 | G29: новое | H29: Lulu's rocking horse, the dog's house; только ед. ч. | I29: 7–9 | J29: =IFERROR(INDEX('Уроки'!$H:$H,MATCH(F29,'Уроки'!$A:$A,0)),"") | K29: =IFERROR(INDEX('Уроки'!$J:$J,MATCH(F29,'Уроки'!$A:$A,0)),"") | L29: Spotlight / 3 класс / Module 4 · Come in and play! / Possessive case ('s) / Possessive case ('s): 's в ед. ч. — принадлежность
A30: 3 | B30: Module 4 · Come in and play! | D30: Possessive case ('s) | E30: Possessive case ('s): вопрос Whose? | F30: Мл-064 | G30: новое | H30: кому принадлежит | I30: 7–9 | J30: =IFERROR(INDEX('Уроки'!$H:$H,MATCH(F30,'Уроки'!$A:$A,0)),"") | K30: =IFERROR(INDEX('Уроки'!$J:$J,MATCH(F30,'Уроки'!$A:$A,0)),"") | L30: Spotlight / 3 класс / Module 4 · Come in and play! / Possessive case ('s) / Possessive case ('s): вопрос Whose?
A31: 3 | B31: Module 4 · Come in and play! | D31: a/an | E31: a/an: неопределённый артикль — только с исчисляемыми в ед. ч. | F31: Мл-065 | G31: новое | H31: the не дан | I31: 7–9 | J31: =IFERROR(INDEX('Уроки'!$H:$H,MATCH(F31,'Уроки'!$A:$A,0)),"") | K31: =IFERROR(INDEX('Уроки'!$J:$J,MATCH(F31,'Уроки'!$A:$A,0)),"") | L31: Spotlight / 3 класс / Module 4 · Come in and play! / a/an / a/an: неопределённый артикль — только с исчисляемыми в ед. ч.
A32: 3 | B32: Module 4 · Come in and play! | D32: a/an | E32: a/an: a перед согласной, an перед гласной | F32: Мл-066 | G32: новое | H32: a ball, an elephant | I32: 7–9 | J32: =IFERROR(INDEX('Уроки'!$H:$H,MATCH(F32,'Уроки'!$A:$A,0)),"") | K32: =IFERROR(INDEX('Уроки'!$J:$J,MATCH(F32,'Уроки'!$A:$A,0)),"") | L32: Spotlight / 3 класс / Module 4 · Come in and play! / a/an / a/an: a перед согласной, an перед гласной
A33: 3 | B33: Module 4 · Come in and play! | D33: Demonstratives (this/that/these/those) | E33: Demonstratives: this — these (ед. и мн. ч.) | F33: Мл-076 | G33: новое | I33: 7–9 | J33: =IFERROR(INDEX('Уроки'!$H:$H,MATCH(F33,'Уроки'!$A:$A,0)),"") | K33: =IFERROR(INDEX('Уроки'!$J:$J,MATCH(F33,'Уроки'!$A:$A,0)),"") | L33: Spotlight / 3 класс / Module 4 · Come in and play! / Demonstratives (this/that/these/those) / Demonstratives: this — these (ед. и мн. ч.)
A34: 3 | B34: Module 4 · Come in and play! | D34: Demonstratives (this/that/these/those) | E34: Demonstratives: that — those (ед. и мн. ч.) | F34: Мл-077 | G34: новое | I34: 7–9 | J34: =IFERROR(INDEX('Уроки'!$H:$H,MATCH(F34,'Уроки'!$A:$A,0)),"") | K34: =IFERROR(INDEX('Уроки'!$J:$J,MATCH(F34,'Уроки'!$A:$A,0)),"") | L34: Spotlight / 3 класс / Module 4 · Come in and play! / Demonstratives (this/that/these/those) / Demonstratives: that — those (ед. и мн. ч.)
A35: 3 | B35: Module 4 · Come in and play! | D35: Demonstratives (this/that/these/those) | E35: Demonstratives: this/these vs that/those — близко vs далеко | F35: Мл-078 | G35: новое | H35: о людях, животных, предметах рядом / далеко | I35: 7–9 | J35: =IFERROR(INDEX('Уроки'!$H:$H,MATCH(F35,'Уроки'!$A:$A,0)),"") | K35: =IFERROR(INDEX('Уроки'!$J:$J,MATCH(F35,'Уроки'!$A:$A,0)),"") | L35: Spotlight / 3 класс / Module 4 · Come in and play! / Demonstratives (this/that/these/those) / Demonstratives: this/these vs that/those — близко vs далеко
A36: 3 | B36: Module 4 · Come in and play! | D36: Question words | E36: Question words: Whose? — чья вещь | F36: Мл-099 | G36: новое | H36: только whose (Whose is this doll?), в разделе Possessive case | I36: 7–9 | J36: =IFERROR(INDEX('Уроки'!$H:$H,MATCH(F36,'Уроки'!$A:$A,0)),"") | K36: =IFERROR(INDEX('Уроки'!$J:$J,MATCH(F36,'Уроки'!$A:$A,0)),"") | L36: Spotlight / 3 класс / Module 4 · Come in and play! / Question words / Question words: Whose? — чья вещь
A37: 3 | B37: Module 5 · Furry friends! | D37: Past Simple | E37: Past Simple: неправильные глаголы — утверждение | F37: Мл-007 | G37: новое | H37: 8 глаголов: say–said, tell–told, go–went, come–came, see–saw, find–found, get–got, have–had (+ make–made) | I37: 7–9 | J37: =IFERROR(INDEX('Уроки'!$H:$H,MATCH(F37,'Уроки'!$A:$A,0)),"") | K37: =IFERROR(INDEX('Уроки'!$J:$J,MATCH(F37,'Уроки'!$A:$A,0)),"") | L37: Spotlight / 3 класс / Module 5 · Furry friends! / Past Simple / Past Simple: неправильные глаголы — утверждение
A38: 3 | B38: Module 5 · Furry friends! | D38: Past Simple | E38: Past Simple: неправильные глаголы — отрицание (didn't go) | F38: Мл-008 | G38: новое | H38: didn't see | I38: 7–9 | J38: =IFERROR(INDEX('Уроки'!$H:$H,MATCH(F38,'Уроки'!$A:$A,0)),"") | K38: =IFERROR(INDEX('Уроки'!$J:$J,MATCH(F38,'Уроки'!$A:$A,0)),"") | L38: Spotlight / 3 класс / Module 5 · Furry friends! / Past Simple / Past Simple: неправильные глаголы — отрицание (didn't go)
A39: 3 | B39: Module 5 · Furry friends! | D39: Past Simple | E39: Past Simple: неправильные глаголы — вопросы (Did … go?) | F39: Мл-009 | G39: новое | H39: Did he go …? | I39: 7–9 | J39: =IFERROR(INDEX('Уроки'!$H:$H,MATCH(F39,'Уроки'!$A:$A,0)),"") | K39: =IFERROR(INDEX('Уроки'!$J:$J,MATCH(F39,'Уроки'!$A:$A,0)),"") | L39: Spotlight / 3 класс / Module 5 · Furry friends! / Past Simple / Past Simple: неправильные глаголы — вопросы (Did … go?)
A40: 3 | B40: Module 5 · Furry friends! | D40: Past Simple | E40: Past Simple: значение — действие в прошлом (yesterday, ago) | F40: Мл-010 | G40: повторение | I40: 7–9 | J40: =IFERROR(INDEX('Уроки'!$H:$H,MATCH(F40,'Уроки'!$A:$A,0)),"") | K40: =IFERROR(INDEX('Уроки'!$J:$J,MATCH(F40,'Уроки'!$A:$A,0)),"") | L40: Spotlight / 3 класс / Module 5 · Furry friends! / Past Simple / Past Simple: значение — действие в прошлом (yesterday, ago)
A41: 3 | B41: Module 5 · Furry friends! | D41: can (ability) | E41: can (ability): значение — умение; утверждение can + глагол без to | F41: Мл-034 | G41: новое | H41: все лица; способность, умение | I41: 7–9 | J41: =IFERROR(INDEX('Уроки'!$H:$H,MATCH(F41,'Уроки'!$A:$A,0)),"") | K41: =IFERROR(INDEX('Уроки'!$J:$J,MATCH(F41,'Уроки'!$A:$A,0)),"") | L41: Spotlight / 3 класс / Module 5 · Furry friends! / can (ability) / can (ability): значение — умение; утверждение can + глагол без to
A42: 3 | B42: Module 5 · Furry friends! | D42: can (ability) | E42: can (ability): отрицание — cannot / can't | F42: Мл-035 | G42: новое | H42: cannot (полное), can't (краткое) | I42: 7–9 | J42: =IFERROR(INDEX('Уроки'!$H:$H,MATCH(F42,'Уроки'!$A:$A,0)),"") | K42: =IFERROR(INDEX('Уроки'!$J:$J,MATCH(F42,'Уроки'!$A:$A,0)),"") | L42: Spotlight / 3 класс / Module 5 · Furry friends! / can (ability) / can (ability): отрицание — cannot / can't
A43: 3 | B43: Module 5 · Furry friends! | D43: can (ability) | E43: can (ability): вопросы и краткие ответы | F43: Мл-036 | G43: новое | H43: Yes, I can / No, he can't | I43: 7–9 | J43: =IFERROR(INDEX('Уроки'!$H:$H,MATCH(F43,'Уроки'!$A:$A,0)),"") | K43: =IFERROR(INDEX('Уроки'!$J:$J,MATCH(F43,'Уроки'!$A:$A,0)),"") | L43: Spotlight / 3 класс / Module 5 · Furry friends! / can (ability) / can (ability): вопросы и краткие ответы
A44: 3 | B44: Module 5 · Furry friends! | D44: have got | E44: have got: утверждение — have got / has got (полные и краткие формы) | F44: Мл-037 | G44: новое | H44: все лица, полные и краткие (I've got, he's got) | I44: 7–9 | J44: =IFERROR(INDEX('Уроки'!$H:$H,MATCH(F44,'Уроки'!$A:$A,0)),"") | K44: =IFERROR(INDEX('Уроки'!$J:$J,MATCH(F44,'Уроки'!$A:$A,0)),"") | L44: Spotlight / 3 класс / Module 5 · Furry friends! / have got / have got: утверждение — have got / has got (полные и краткие формы)
A45: 3 | B45: Module 5 · Furry friends! | D45: have got | E45: have got: отрицание — haven't got / hasn't got | F45: Мл-038 | G45: новое | H45: полные и краткие | I45: 7–9 | J45: =IFERROR(INDEX('Уроки'!$H:$H,MATCH(F45,'Уроки'!$A:$A,0)),"") | K45: =IFERROR(INDEX('Уроки'!$J:$J,MATCH(F45,'Уроки'!$A:$A,0)),"") | L45: Spotlight / 3 класс / Module 5 · Furry friends! / have got / have got: отрицание — haven't got / hasn't got
A46: 3 | B46: Module 5 · Furry friends! | D46: have got | E46: have got: вопросы и краткие ответы | F46: Мл-039 | G46: новое | H46: Have you got…? Has he got…?; got в ответе опускается | I46: 7–9 | J46: =IFERROR(INDEX('Уроки'!$H:$H,MATCH(F46,'Уроки'!$A:$A,0)),"") | K46: =IFERROR(INDEX('Уроки'!$J:$J,MATCH(F46,'Уроки'!$A:$A,0)),"") | L46: Spotlight / 3 класс / Module 5 · Furry friends! / have got / have got: вопросы и краткие ответы
A47: 3 | B47: Module 5 · Furry friends! | D47: have got | E47: have got: значение — принадлежность (иметь) | F47: Мл-040 | G47: новое | H47: She has got a rabbit | I47: 7–9 | J47: =IFERROR(INDEX('Уроки'!$H:$H,MATCH(F47,'Уроки'!$A:$A,0)),"") | K47: =IFERROR(INDEX('Уроки'!$J:$J,MATCH(F47,'Уроки'!$A:$A,0)),"") | L47: Spotlight / 3 класс / Module 5 · Furry friends! / have got / have got: значение — принадлежность (иметь)
A48: 3 | B48: Module 5 · Furry friends! | D48: have got | E48: have got: значение — описание внешности людей, животных, предметов | F48: Мл-041 | G48: новое | H48: It's got a big mouth | I48: 7–9 | J48: =IFERROR(INDEX('Уроки'!$H:$H,MATCH(F48,'Уроки'!$A:$A,0)),"") | K48: =IFERROR(INDEX('Уроки'!$J:$J,MATCH(F48,'Уроки'!$A:$A,0)),"") | L48: Spotlight / 3 класс / Module 5 · Furry friends! / have got / have got: значение — описание внешности людей, животных, предметов
A49: 3 | B49: Module 5 · Furry friends! | D49: have got | E49: have got: It's got (= It has got) vs It's (= It is) | F49: Мл-042 | G49: новое | H49: It's got = It has got; It's = It is | I49: 7–9 | J49: =IFERROR(INDEX('Уроки'!$H:$H,MATCH(F49,'Уроки'!$A:$A,0)),"") | K49: =IFERROR(INDEX('Уроки'!$J:$J,MATCH(F49,'Уроки'!$A:$A,0)),"") | L49: Spotlight / 3 класс / Module 5 · Furry friends! / have got / have got: It's got (= It has got) vs It's (= It is)
A50: 3 | B50: Module 5 · Furry friends! | D50: Plurals (irregular) | E50: Plurals (irregular): man — men, child — children, tooth — teeth, foot — feet, mouse — mice | F50: Мл-057 | G50: новое | H50: + woman — women | I50: 7–9 | J50: =IFERROR(INDEX('Уроки'!$H:$H,MATCH(F50,'Уроки'!$A:$A,0)),"") | K50: =IFERROR(INDEX('Уроки'!$J:$J,MATCH(F50,'Уроки'!$A:$A,0)),"") | L50: Spotlight / 3 класс / Module 5 · Furry friends! / Plurals (irregular) / Plurals (irregular): man — men, child — children, tooth — teeth, foot — feet, mouse — mice
...

Sheet Пересечения
A1: № | B1: Что повторяется | C1: Где встречается (тема: подтема — классы) | D1: Где живёт урок (предложение) | E1: Что делать в остальных местах | F1: Решение методиста
A2: 1 | B2: a few / a little | C2: • a few/a little — 6 подтем, 5–11 кл. • Quantifiers: a few/few vs a little/little — 8 кл. | D2: a few/a little | E2: Quantifiers 8 кл. — ссылка на уроки a few/a little, своего урока не делать.
A3: 2 | B3: much / many / a lot of | C3: • much/many/a lot of — 5 подтем, 4–11 кл. • Quantifiers: a lot of / lots of; much/many — отрицания и вопросы — 8 кл. | D3: much/many/a lot of | E3: Quantifiers 8 кл. — ссылка.
A4: 3 | B4: every / each | C4: • Determiners (every/each) — 4 подтемы, 9–10 кл. • Quantifiers: every vs each — 11 кл. • Indefinite pronouns: every + ед. ч.; everybody, everything — 9, 11 кл. | D4: Determiners (every/each) | E4: Quantifiers 11 кл. — ссылка. В Indefinite pronouns оставить только производные everybody/everything/everywhere.
A5: 4 | B5: hardly any | C5: • Indefinite pronouns: hardly any — 9, 11 кл. • Quantifiers: hardly any — 11 кл. | D5: Indefinite pronouns | E5: Quantifiers — ссылка. У Quantifiers остаются свои уроки: a couple of / several; a great deal of / plenty of.
A6: 5 | B6: a bottle of, a packet of… (количество неисчисляемых) | C6: • Partitives — 2 подтемы, 7 кл. • Countable / Uncountable: количество с неисчисляемыми (a jar of, a bottle of) — 5, 6, 11 кл. | D6: Partitives (a bottle of…) | E6: Подтема в Countable / Uncountable — ссылка на урок Partitives (обе в группе 10+, урок один).
A7: 6 | B7: Существительные только во мн. ч. (jeans, scissors, clothes) | C7: • Plurals (irregular): только во мн. ч. — 5 кл. • Countable / Uncountable: существительные без ед. числа — 5 кл. • Plurals (only plural / collective nouns): только мн. ч. — 8 кл. | D7: Plurals (only plural / collective nouns) | E7: В 5 кл. обе подтемы — ссылка на этот урок.
A8: 7 | B8: Собирательные существительные (family, team, police) | C8: • Plurals (only plural / collective nouns): собирательные — 8 кл. • Countable / Uncountable: собирательные и составные — 11 кл. | D8: Plurals (only plural / collective nouns) | E8: Countable 11 кл. — ссылка; составные (homework, countryside) оставить в Countable.
A9: 8 | B9: some / any с существительными | C9: • a/an/some/any — 6 подтем, 3–7 кл. • Indefinite pronouns: some/any/no + неисчисляемые и мн. ч.; some в просьбах; any в вопросах и отрицаниях — 9–11 кл. | D9: a/an/some/any (some/any + существительное) | E9: В Indefinite pronouns оставить то, чего нет в a/an/some/any: производные (somebody, anything, nowhere), no- вместо not any, any = «любой», глагол в ед. ч. Остальное — ссылка. У 3 кл. (7–9 лет) урок свой в любом случае.
A10: 9 | B10: There is / There are | C10: • There is / There are — 3, 5 кл. • Countable / Uncountable: There is/are + исчисляемые/неисчисляемые (утв., отр., вопрос) — 7 кл. | D10: There is / There are | E10: Countable 7 кл. — ссылка (для 10+ урок There is/are уже есть с 5 кл.).
A11: 10 | B11: Запрет: mustn't / can't | C11: • must/mustn't: mustn't — запрет (4–10 кл.); can't как запрет (6, 8, 10 кл.) • can (permission/request): can't — запрет (5, 6, 9, 10, 11 кл.) | D11: must/mustn't — один урок «Запрет: mustn't и can't» | E11: can (permission/request) — ссылка; в нём остаются Can I…? / Can you…? / can vs may.
A12: 11 | B12: Обязанность: must vs have to, had to | C12: • must/mustn't: must только в настоящем, в других временах have to / had to — 7–9 кл. • have to: had to, didn't have to — 7–10 кл. • must/have to (obligation): must vs have to; had to; should/ought to — долг — 11 кл. • should/shouldn't: обязательство, долг — 8–10 кл. | D12: must/have to (obligation) — урок-сравнение «must vs have to» | E12: had to / didn't have to — урок в have to; «долг» should/ought to — урок в should. Подтема в must/mustn't и в must/have to 11 кл. — ссылки.
A13: 12 | B13: Совет: should / ought to / shall / had better | C13: • should/shouldn't: совет; ought to; Shall I…? — совет; had better — 7–11 кл. • Modal verbs (functions): совет (should / ought to / shall) — 8, 9 кл. • Semi-modals: had better (= should) — 11 кл. | D13: should/shouldn't | E13: Modal verbs (functions) и Semi-modals — ссылки.
... A24: 23 | B24: Reported questions и Indirect questions | C24: • Reported questions — 5 подтем, 8–11 кл. • Indirect questions — 3 подтемы, 8–11 кл. | D24: это НЕ дубль | E24: Reported questions — пересказ чужого вопроса со сдвигом времён; Indirect questions — вежливый вопрос (Could you tell me…?) без сдвига. Оба урока нужны; в каждом полезно показать разницу.

Sheet Кандидаты в вебинары
A1: Группа | B1: Тема | C1: С какого класса | D1: Подтем без ничего (красные) | E1: из них новое в учебнике | F1: Красные подтемы | G1: Остальные подтемы темы
A2: 7–9 | B2: Prepositions of place | C2: 3 кл. | D2: 1 | E2: 1 | F2: • opposite, between | G2: с видео: 2
A3: 7–9 | B3: Present Simple | C3: 3 кл. | D3: 1 | E3: 1 | F3: • произношение окончания -s/-es (/s/, /z/, /ɪz/) | G3: с видео: 3, вебинар в расписании: 3
A4: 7–9 | B4: There is / There are | C4: 3 кл. | D4: 1 | E4: 1 | F4: • вопросы — Is there…? / Are there…? | G4: с видео: 3
A5: 7–9 | B5: a/an | C5: 3 кл. | D5: 1 | E5: 1 | F5: • неопределённый артикль — только с исчисляемыми в ед. ч. | G5: с видео: 1
A6: 7–9 | B6: Comparatives & Superlatives | C6: 4 кл. | D6: 2 | E6: 2 | F6: • превосходная степень — the most • двусложные на -y/-er/-ow — -er/-est | G6: с видео: 4, вебинар в расписании: 1
A7: 7–9 | B7: Ordinal numbers | C7: 4 кл. | D7: 1 | E7: 1 | F7: • с артиклем the и даты | G7: с видео: 2
A8: 7–9 | B8: have to | C8: 4 кл. | D8: 1 | E8: 1 | F8: • вопросы и краткие ответы — Do you have to…? | G8: с видео: 2
A9: 10+ | B9: Word formation | C9: 5 кл. | D9: 22 | E9: 22 | F9: • -able, -ous, -ing • -al • -er, -or, -man, -ist, -ic • -ly • -tion, -sion • conversion (a dress – to dress) • nationalities -an/-ish/-ian/-ese • un- • -ion, -tion, -ance • -ise, -ize • -ness, -ment • il-, im-, in-, ir- • negative adjectives • abstract nouns • nouns from adjectives • participle adjectives -ed/-ing • revision • verbs from nouns/adjectives • verbs with prefixes • forming verbs • personal nouns • prefixes | G9: с видео: 6
A10: 10+ | B10: Present Simple | C10: 5 кл. | D10: 10 | E10: 5 | F10: • утверждение (I/you/we/they V, he/she/it V-s) • отрицание (don't/doesn't) • общие вопросы (Do/Does …?) • краткие ответы (Yes, I do / No, he doesn't) • орфография окончания -s/-es (3 л. ед. ч.) • значение — непреложные истины и законы природы • значение — чувства и эмоции • значение — обзоры, спортивные комментарии, повествование • значение — восклицания (Here comes …!) • значение — последовательные действия в настоящем | G10: с видео: 3
A11: 10+ | B11: Prepositions of place | C11: 5 кл. | D11: 8 | E11: 5 | F11: • in, on, under • next to, in front of, behind • opposite, between • near, beside • at — at school/work/home, в адресах • in — устойчивые выражения (in bed, in hospital, in the sky, in a picture) • in — города, страны, континенты • on — on the left/right, on the first floor
A12: 10+ | B12: Past Simple | C12: 5 кл. | D12: 7 | E12: 2 | F12: • правильные глаголы — отрицание (didn't + V) • правильные глаголы — вопросы (Did …?) • краткие ответы (Yes, I did / No, I didn't) • неправильные глаголы — отрицание (didn't go) • неправильные глаголы — вопросы (Did … go?) • значение — повторяющиеся действия и привычки в прошлом • значение — завершённые действия без связи с настоящим | G12: с видео: 6, вебинар в расписании: 1
A13: 10+ | B13: Present Continuous | C13: 5 кл. | D13: 7 | E13: 3 | F13: • утверждение (am/is/are + V-ing) • отрицание (I'm not / isn't / aren't) • общие вопросы (Am/Is/Are …?) • краткие ответы (Yes, I am / No, he isn't) • орфография -ing • значение — меняющиеся и развивающиеся ситуации • значение — always + раздражение | G13: с видео: 4
A14: 10+ | B14: Articles (a/an/the/zero) | C14: 5 кл. | D14: 6 | E14: 6 | F14: • нулевой артикль — при другом определителе (my, this, some, числительное, 's) • a/an = per; деньги, дроби, меры, частота, скорость • a/an с болезнями (a cold, но flu) • a/the + ед. ч. — обобщение группы • the и нулевой — театры, отели, музеи, газеты; названия с именем (Victoria Station, Harrods) • the — люди: фамилии, титулы, the + прилагательное (the rich) | G14: с видео: 6, вебинар в расписании: 1
A15: 10+ | B15: Plurals (regular) | C15: 5 кл. | D15: 6 | E15: 2 | F15: • основное правило — + -s • орфография — + -es после -s, -ss, -sh, -ch, -x, -o • орфография — -y → -ies (но гласная + y → -s) • орфография — -f/-fe → -ves • исключения на -o — только -s (photos, videos) • произношение окончания -(e)s
A16: 10+ | B16: Prepositions of time | C16: 5 кл. | D16: 6 | E16: 3 | F16: • at — время, праздники, at night/at noon/at the weekend • on — дни недели и праздничные дни • on — даты, день недели + часть дня, on a hot day • in — части суток (in the morning/afternoon/evening) • in — месяцы, времена года, годы, века • in = «через» (in an hour, in a week)
A17: 10+ | B17: have got | C17: 5 кл. | D17: 6 | E17: 1 | F17: • утверждение — have got / has got (полные и краткие формы) • отрицание — haven't got / hasn't got • вопросы и краткие ответы • значение — принадлежность (иметь) • значение — описание внешности людей, животных, предметов • значение — родственные отношения
A18: 10+ | B18: Comparatives & Superlatives | C18: 5 кл. | D18: 5 | E18: 2 | F18: • орфография -er/-est (удвоение, -e, y → i) • неправильные прилагательные (good, bad, many/much, little) • двусложные на -y/-er/-ow — -er/-est • прилагательные с двумя способами (clever, quiet, friendly…) • far — farther/further, old — elder/eldest | G18: с видео: 7
A19: 10+ | B19: There is / There are | C19: 5 кл. | D19: 5 | E19: 1 | F19: • there is — утверждение (ед. ч.) • there are — утверждение (мн. ч.) • отрицание — there isn't / there aren't • вопросы — Is there…? / Are there…? • some / any в конструкции
A20: 10+ | B20: Countable / Uncountable nouns | C20: 5 кл. | D20: 4 | E20: 4 | F20: • исключения с a/an (a help, a pity, a shame) • группы неисчисляемых — предметы, языки, игры, болезни, явления природы • «ловушки» — advice, information, news, furniture, luggage, money • длительность, расстояние, деньги как целое — глагол в ед. ч. | G20: с видео: 9
A21: 10+ | B21: can (permission/request) | C21: 5 кл. | D21: 4 | E21: 4 | F21: • просьба — Can you…? / Can I have…? • предложение помощи — Can I…? • can vs may — разрешение (may формальнее) • предложения (offers/suggestions) — can, could, would, shall | G21: с видео: 2
A22: 10+ | B22: must/mustn't | C22: 5 кл. | D22: 4 | E22: 4 | F22: • can't как запрет (= mustn't) • must — настойчивый совет • must только в настоящем; в других временах — have to / had to • must — логический вывод | G22: с видео: 2
A23: 10+ | B23: Imperative | C23: 5 кл. | D23: 3 | E23: 3 | F23: • значение — инструкция, указание • значение — предложение (Have some cake) • значение — просьба, вежливость с please | G23: с видео: 3
A24: 10+ | B24: Personal pronouns (subject) | C24: 5 кл. | D24: 3 | E24: 3 | F24: • формы I, you, he, she, it, we, you, they • употребление — подлежащее вместо существительного • he/she vs it vs they — выбор местоимения
A25: 10+ | B25: Present Simple vs Present Continuous | C25: 5 кл. | D25: 3 | E25: 3 | F25: • постоянное состояние vs временная ситуация • повторяющиеся действия vs настоящий период (these days) • будущее — расписание vs договорённость | G25: с видео: 1
A26: 10+ | B26: a/an/some/any | C26: 5 кл. | D26: 3 | E26: 2 | F26: • some в вопросах — просьба и предложение • a/an vs some/any — исчисляемые ед. ч. во всех типах предложений • перевод some — «несколько» / «немного» / не переводится | G26: с видео: 3
A27: 10+ | B27: can (ability) | C27: 5 кл. | D27: 3 | E27: 0 | F27: • значение — умение; утверждение can + глагол без to • отрицание — cannot / can't • вопросы и краткие ответы
A28: 10+ | B28: to be (Past: was/were) | C28: 5 кл. | D28: 3 | E28: 0 | F28: • утверждение — was / were • отрицание — wasn't / weren't • вопросы и краткие ответы
A29: 10+ | B29: to be (Present) | C29: 5 кл. | D29: 3 | E29: 0 | F29: • утверждение — am/is/are, полные и краткие формы • отрицание — am not / isn't / aren't • вопросы и краткие ответы
A30: 10+ | B30: Adverbs of frequency | C30: 5 кл. | D30: 2 | E30: 2 | F30: • место — после вспомогательных и модальных глаголов • seldom / rarely | G30: с видео: 3
A31: 10+ | B31: Demonstratives (this/that/these/those) | C31: 5 кл. | D31: 2 | E31: 0 | F31: • this — these (ед. и мн. ч.) • that — those (ед. и мн. ч.)
A32: 10+ | B32: Future Simple (will) | C32: 5 кл. | D32: 2 | E32: 2 | F32: • значение — надежды, страхи, предложения, комментарии • значение — неизбежные события (не зависят от нас) | G32: с видео: 2, вебинар в расписании: 8
A33: 10+ | B33: Possessive case ('s) | C33: 5 кл. | D33: 2 | E33: 2 | F33: • значение — отношения между людьми • магазины, учреждения, чей-то дом (at the baker's) | G33: вебинар в расписании: 5
A34: 10+ | B34: Present Perfect | C34: 5 кл. | D34: 2 | E34: 2 | F34: • значение — неуказанное время в прошлом • значение — акцент на количестве (seven times this week) | G34: с видео: 8, вебинар в расписании: 3
A35: 10+ | B35: Question tags | C35: 5 кл. | D35: 2 | E35: 2 | F35: • have (владеть) → haven't I? vs have в идиоме → don't I? • This/That is → isn't it? | G35: с видео: 3, вебинар в расписании: 5
A36: 10+ | B36: a few/a little | C36: 5 кл. | D36: 2 | E36: 2 | F36: • very few / very little • a little + прилагательное (a little cold) | G36: с видео: 4
A37: 10+ | B37: Object pronouns | C37: 5 кл. | D37: 1 | E37: 1 | F37: • личные vs объектные vs притяжательные — сопоставление | G37: с видео: 2
A38: 10+ | B38: much/many/a lot of | C38: 5 кл. | D38: 1 | E38: 0 | F38: • краткие ответы и a lot / lots без существительного | G38: с видео: 4
A39: 10+ | B39: need/needn't | C39: 6 кл. | D39: 4 | E39: 4 | F39: • needn't / don't need to — нет необходимости (наст./буд.) • needn't have V3 — не было необходимости, но сделали • needn't have vs didn't have to • need (= must) как эквивалент модального
A40: 10+ | B40: Ordinal numbers | C40: 6 кл. | D40: 3 | E40: 0 | F40: • first, second, third и составные (21st, 22nd) • образование с -th и орфография (fifth, ninth, twelfth, twentieth) • с артиклем the и даты
...

Sheet Итоги
A1: Группа | B1: Классы | C1: Уроков сделать | D1: Есть видео (зелёные) | E1: Вебинар в расписании (жёлтые) | F1: Только материалы (оранжевые) | G1: Ничего нет (красные) | H1: Готовы | I1: Опубликованы | J1: Мест в папках (урок × класс × модуль)
A2: 7–9 | B2: 3, 4 | C2: =COUNTIF('Уроки'!B:B,"7–9") | D2: =COUNTIFS('Уроки'!B:B,"7–9",'Уроки'!H:H,"видео") | E2: =COUNTIFS('Уроки'!B:B,"7–9",'Уроки'!H:H,"вебинар") | F2: =COUNTIFS('Уроки'!B:B,"7–9",'Уроки'!H:H,"материалы") | G2: =COUNTIFS('Уроки'!B:B,"7–9",'Уроки'!H:H,"нет") | H2: =COUNTIFS('Уроки'!B:B,"7–9",'Уроки'!J:J,"готов*") | I2: =COUNTIFS('Уроки'!B:B,"7–9",'Уроки'!J:J,"опубликован") | J2: =COUNTIF('Папки уроков'!I:I,"7–9")
